{
	"id": "SUSE-SU-2019:2379-1",
	"modified": "2019-09-16T08:44:56Z",
	"published": "2019-09-16T08:44:56Z",
	"related": [
		"CVE-2019-12781"
	],
	"summary": "Security update for python-Django",
	"details": "This update for python-Django fixes the following issues:\n\nSecurity issue fixed:\n\n- CVE-2019-12781: Add incorrect HTTP detection with reverse-proxy connecting via HTTPS (bsc#1139945).\n",
	"affected": [
		{
			"package": {
				"ecosystem": "SUSE:OpenStack Cloud 7",
				"name": "python-Django",
				"purl": "purl:rpm/suse/python-Django&distro=SUSE%20OpenStack%20Cloud%207"
			},
			"ranges": [
				{
					"type": "ECOSYSTEM",
					"events": [
						{
							"introduced": "0"
						},
						{
							"fixed": "1.8.19-3.18.1"
						}
					]
				}
			],
			"ecosystem_specific": {
				"binaries": [
					{
						"python-Django": "1.8.19-3.18.1"
					}
				]
			}
		}
	],
	"references": [
		{
			"type": "ADVISORY",
			"url": "https://www.suse.com/support/update/announcement/2019/suse-su-20192379-1/"
		},
		{
			"type": "REPORT",
			"url": "https://bugzilla.suse.com/1139945"
		},
		{
			"type": "WEB",
			"url": "https://www.suse.com/security/cve/CVE-2019-12781"
		}
	]
}
